<?xml version="1.0" encoding="UTF-8"?>
<!-- Generated by org.testng.reporters.JUnitReportReporter -->
<testsuite ignored="0" hostname="DESKTOP-SKD8PO3" failures="1" tests="8" name="testng.FailedTest2" time="0.028" errors="0" timestamp="08 Apr 2025 14:45:32 GMT" skipped="4">
  <testcase classname="testng.FailedTest2" name="user" time="0.006">
    <skipped/>
  </testcase> <!-- user -->
  <testcase classname="testng.FailedTest2" name="f" time="0.002"/>
  <testcase classname="testng.FailedTest2" name="user" time="0.001">
    <skipped/>
  </testcase> <!-- user -->
  <testcase classname="testng.FailedTest2" name="d" time="0.013"/>
  <testcase classname="testng.FailedTest2" name="user" time="0.001">
    <skipped/>
  </testcase> <!-- user -->
  <testcase classname="testng.FailedTest2" name="user" time="0.002">
    <failure message="expected [grace] but found [Grace]" type="java.lang.AssertionError">
      <![CDATA[java.lang.AssertionError: expected [grace] but found [Grace]
	at org.testng.Assert.fail(Assert.java:94)
	at org.testng.Assert.failNotEquals(Assert.java:513)
	at org.testng.Assert.assertEqualsImpl(Assert.java:135)
	at org.testng.Assert.assertEquals(Assert.java:116)
	at org.testng.Assert.assertEquals(Assert.java:190)
	at org.testng.Assert.assertEquals(Assert.java:200)
	at testng.FailedTest2.user(FailedTest2.java:11)
	at java.base/jdk.internal.reflect.DirectMethodHandleAccessor.invoke(DirectMethodHandleAccessor.java:103)
	at java.base/java.lang.reflect.Method.invoke(Method.java:580)
	at org.testng.internal.MethodInvocationHelper.invokeMethod(MethodInvocationHelper.java:104)
	at org.testng.internal.Invoker.invokeMethod(Invoker.java:645)
	at org.testng.internal.Invoker.retryFailed(Invoker.java:998)
	at org.testng.internal.Invoker.invokeTestMethods(Invoker.java:1200)
	at org.testng.internal.TestMethodWorker.invokeTestMethods(TestMethodWorker.java:129)
	at org.testng.internal.TestMethodWorker.run(TestMethodWorker.java:112)
	at org.testng.TestRunner.privateRun(TestRunner.java:756)
	at org.testng.TestRunner.run(TestRunner.java:610)
	at org.testng.SuiteRunner.runTest(SuiteRunner.java:387)
	at org.testng.SuiteRunner.runSequentially(SuiteRunner.java:382)
	at org.testng.SuiteRunner.privateRun(SuiteRunner.java:340)
	at org.testng.SuiteRunner.run(SuiteRunner.java:289)
	at org.testng.SuiteRunnerWorker.runSuite(SuiteRunnerWorker.java:52)
	at org.testng.SuiteRunnerWorker.run(SuiteRunnerWorker.java:86)
	at org.testng.TestNG.runSuitesSequentially(TestNG.java:1293)
	at org.testng.TestNG.runSuitesLocally(TestNG.java:1218)
	at org.testng.TestNG.runSuites(TestNG.java:1133)
	at org.testng.TestNG.run(TestNG.java:1104)
	at org.testng.remote.AbstractRemoteTestNG.run(AbstractRemoteTestNG.java:115)
	at org.testng.remote.RemoteTestNG.initAndRun(RemoteTestNG.java:293)
	at org.testng.remote.RemoteTestNG.main(RemoteTestNG.java:91)
]]>
    </failure>
  </testcase> <!-- user -->
  <testcase classname="testng.FailedTest2" name="e" time="0.002"/>
  <testcase classname="testng.FailedTest2" name="user" time="0.001">
    <skipped/>
  </testcase> <!-- user -->
</testsuite> <!-- testng.FailedTest2 -->
